2022-05-24 09:53:25,948 - DataLoaderLogger - INFO - DVC: CSV file read with path: data/raw/store.csv | version: raw_data | from: ../
2022-05-24 10:19:48,749 - DataLoaderLogger - INFO - DVC: CSV file read with path: data/raw/store.csv | version: raw_data | from: ../
2022-05-24 10:39:55,500 - DataLoaderLogger - INFO - DVC: CSV file read with path: data/raw/store.csv | version: raw_data | from: ../
2022-05-24 10:42:18,669 - DataLoaderLogger - INFO - DVC: CSV file read with path: data/raw/store.csv | version: raw_data | from: ../
2022-05-24 10:48:06,114 - DataLoaderLogger - INFO - DVC: CSV file read with path: data/raw/store.csv | version: raw_data | from: ../
2022-05-24 10:48:32,194 - DataLoaderLogger - INFO - DVC: CSV file read with path: data/raw/store.csv | version: raw_data | from: ../
2022-05-24 12:37:05,425 - DataLoaderLogger - INFO - DVC: CSV file read with path: data/raw/store.csv | version: raw_data | from: ../
2022-05-24 14:50:14,084 - DataLoaderLogger - INFO - DVC: CSV file read with path: data/raw/train.csv | version: raw_data | from: ../
2022-05-24 15:47:41,961 - DataLoaderLogger - INFO - DVC: CSV file read with path: data/raw/train.csv | version: raw_data | from: ../
2022-05-24 15:49:17,365 - DataLoaderLogger - INFO - DVC: CSV file read with path: data/raw/train.csv | version: raw_data | from: ../
2022-05-24 17:24:46,378 - DataLoaderLogger - INFO - DVC: CSV file read with path: data/raw/train.csv | version: raw_data | from: ../
2022-05-24 17:28:43,564 - DataLoaderLogger - INFO - DVC: CSV file read with path: data/raw/train.csv | version: raw_data | from: ../
2022-05-24 17:44:23,892 - DataLoaderLogger - INFO - DVC: CSV file read with path: data/raw/store.csv | version: raw_data | from: ../
2022-05-24 17:50:01,623 - DataLoaderLogger - INFO - DVC: CSV file read with path: data/raw/store.csv | version: raw_data | from: ../
2022-05-24 17:53:11,472 - DataLoaderLogger - INFO - DVC: CSV file read with path: data/raw/store.csv | version: raw_data | from: ../
2022-05-24 17:53:21,609 - DataLoaderLogger - INFO - DVC: CSV file read with path: data/raw/train.csv | version: raw_data | from: ../
2022-05-24 17:57:09,333 - DataLoaderLogger - INFO - DVC: CSV file read with path: data/raw/store.csv | version: raw_data | from: ../
2022-05-24 18:00:28,309 - DataLoaderLogger - INFO - DVC: CSV file read with path: data/raw/train.csv | version: raw_data | from: ../
2022-05-24 18:04:53,996 - DataLoaderLogger - INFO - DVC: CSV file read with path: data/raw/store.csv | version: raw_data | from: ../
2022-05-24 18:14:42,951 - DataLoaderLogger - INFO - DVC: CSV file read with path: data/raw/train.csv | version: raw_data | from: ../
2022-05-24 18:24:46,256 - DataLoaderLogger - INFO - DVC: CSV file read with path: data/cleaned/store.csv | version: stores_missing_filled | from: ../
2022-05-24 18:24:47,325 - DataLoaderLogger - INFO - DVC: CSV file read with path: data/raw/train.csv | version: raw_data | from: ../
2022-05-24 18:26:16,921 - DataLoaderLogger - INFO - DVC: CSV file read with path: data/raw/store.csv | version: raw_data | from: ../
2022-05-24 18:27:23,187 - DataLoaderLogger - INFO - DVC: CSV file read with path: data/raw/store.csv | version: raw_data | from: ../
2022-05-24 18:31:52,399 - DataLoaderLogger - INFO - DVC: CSV file read with path: data/cleaned/store.csv | version: stores_missing_filled_v2 | from: ../
2022-05-24 18:31:53,977 - DataLoaderLogger - INFO - DVC: CSV file read with path: data/raw/train.csv | version: raw_data | from: ../
2022-05-24 19:52:33,282 - DataLoaderLogger - INFO - DVC: CSV file read with path: data/cleaned/store.csv | version: stores_missing_filled_v2 | from: ../
2022-05-24 19:52:34,946 - DataLoaderLogger - INFO - DVC: CSV file read with path: data/raw/train.csv | version: raw_data | from: ../
2022-05-25 01:27:54,434 - DataLoaderLogger - INFO - DVC: CSV file read with path: data/cleaned/store.csv | version: stores_missing_filled_v2 | from: ../
2022-05-25 01:27:57,457 - DataLoaderLogger - INFO - DVC: CSV file read with path: data/raw/train.csv | version: raw_data | from: ../
2022-05-25 01:28:21,326 - DataLoaderLogger - INFO - DVC: CSV file read with path: data/raw/test.csv | version: raw_data | from: ../
2022-05-25 01:38:32,590 - DataLoaderLogger - INFO - DVC: CSV file read with path: data/cleaned/store.csv | version: stores_missing_filled_v2 | from: ../
2022-05-25 01:38:35,082 - DataLoaderLogger - INFO - DVC: CSV file read with path: data/raw/train.csv | version: raw_data | from: ../
2022-05-25 01:38:44,033 - DataLoaderLogger - INFO - DVC: CSV file read with path: data/raw/test.csv | version: raw_data | from: ../
2022-05-25 01:46:14,210 - DataLoaderLogger - INFO - DVC: CSV file read with path: data/cleaned/store.csv | version: stores_missing_filled_v2 | from: ../
2022-05-25 01:46:16,351 - DataLoaderLogger - INFO - DVC: CSV file read with path: data/raw/train.csv | version: raw_data | from: ../
2022-05-25 01:46:39,945 - DataLoaderLogger - INFO - DVC: CSV file read with path: data/raw/test.csv | version: raw_data | from: ../
2022-05-25 02:19:25,292 - DataLoaderLogger - INFO - DVC: CSV file read with path: data/cleaned/store.csv | version: stores_missing_filled_v2 | from: ../
2022-05-25 02:19:27,181 - DataLoaderLogger - INFO - DVC: CSV file read with path: data/raw/train.csv | version: raw_data | from: ../
2022-05-25 02:19:36,192 - DataLoaderLogger - INFO - DVC: CSV file read with path: data/raw/test.csv | version: raw_data | from: ../
2022-05-25 02:57:10,963 - DataLoaderLogger - INFO - DVC: CSV file read with path: data/cleaned/store.csv | version: stores_missing_filled_v2 | from: ../
2022-05-25 02:57:12,912 - DataLoaderLogger - INFO - DVC: CSV file read with path: data/raw/train.csv | version: raw_data | from: ../
2022-05-25 02:57:25,436 - DataLoaderLogger - INFO - DVC: CSV file read with path: data/raw/test.csv | version: raw_data | from: ../
2022-05-25 03:18:05,943 - DataLoaderLogger - INFO - DVC: CSV file read with path: data/raw/test.csv | version: raw_data | from: ../
2022-05-25 09:12:18,285 - DataLoaderLogger - INFO - DVC: CSV file read with path: data/raw/store.csv | version: raw_data | from: ../
2022-05-25 09:19:59,004 - DataLoaderLogger - INFO - DVC: CSV file read with path: data/cleaned/store.csv | version: stores_v3 | from: ../
2022-05-25 09:20:01,745 - DataLoaderLogger - INFO - DVC: CSV file read with path: data/raw/train.csv | version: raw_data | from: ../
2022-05-25 09:39:41,768 - DataLoaderLogger - INFO - DVC: CSV file read with path: data/cleaned/store.csv | version: stores_v3 | from: ../
2022-05-25 09:39:45,243 - DataLoaderLogger - INFO - DVC: CSV file read with path: data/raw/train.csv | version: raw_data | from: ../
2022-05-25 09:39:45,399 - DataLoaderLogger - INFO - DVC: CSV file read with path: data/raw/test.csv | version: raw_data | from: ../
2022-05-25 09:46:03,553 - DataLoaderLogger - INFO - DVC: CSV file read with path: data/cleaned/store.csv | version: stores_v3 | from: ../
2022-05-25 09:46:05,559 - DataLoaderLogger - INFO - DVC: CSV file read with path: data/raw/train.csv | version: raw_data | from: ../
2022-05-25 09:46:05,702 - DataLoaderLogger - INFO - DVC: CSV file read with path: data/raw/test.csv | version: raw_data | from: ../
2022-05-25 09:46:22,241 - DataLoaderLogger - INFO - DVC: CSV file read with path: data/cleaned/store.csv | version: stores_v3 | from: ../
2022-05-25 09:46:24,326 - DataLoaderLogger - INFO - DVC: CSV file read with path: data/raw/train.csv | version: raw_data | from: ../
2022-05-25 09:46:24,482 - DataLoaderLogger - INFO - DVC: CSV file read with path: data/raw/test.csv | version: raw_data | from: ../
2022-05-25 09:46:34,073 - DataLoaderLogger - INFO - DVC: CSV file read with path: data/cleaned/store.csv | version: stores_v3 | from: ../
2022-05-25 09:46:36,501 - DataLoaderLogger - INFO - DVC: CSV file read with path: data/raw/train.csv | version: raw_data | from: ../
2022-05-25 09:46:36,682 - DataLoaderLogger - INFO - DVC: CSV file read with path: data/raw/test.csv | version: raw_data | from: ../
2022-05-25 09:55:59,085 - DataLoaderLogger - INFO - DVC: CSV file read with path: data/cleaned/store.csv | version: stores_v3 | from: ../
2022-05-25 09:56:00,869 - DataLoaderLogger - INFO - DVC: CSV file read with path: data/raw/train.csv | version: raw_data | from: ../
2022-05-25 09:56:01,032 - DataLoaderLogger - INFO - DVC: CSV file read with path: data/raw/test.csv | version: raw_data | from: ../
2022-05-25 10:04:28,584 - DataLoaderLogger - INFO - DVC: CSV file read with path: data/cleaned/store.csv | version: stores_v3 | from: ../
2022-05-25 10:04:30,684 - DataLoaderLogger - INFO - DVC: CSV file read with path: data/raw/train.csv | version: raw_data | from: ../
2022-05-25 10:04:30,835 - DataLoaderLogger - INFO - DVC: CSV file read with path: data/raw/test.csv | version: raw_data | from: ../
2022-05-25 10:15:46,219 - DataLoaderLogger - INFO - DVC: CSV file read with path: data/cleaned/store.csv | version: stores_v3 | from: ../
2022-05-25 10:15:48,245 - DataLoaderLogger - INFO - DVC: CSV file read with path: data/raw/train.csv | version: raw_data | from: ../
2022-05-25 10:15:48,396 - DataLoaderLogger - INFO - DVC: CSV file read with path: data/raw/test.csv | version: raw_data | from: ../
2022-05-25 10:21:14,535 - DataLoaderLogger - INFO - DVC: CSV file read with path: data/merged/train.csv | version: merged_v1 | from: ../
2022-05-25 10:21:14,802 - DataLoaderLogger - INFO - DVC: CSV file read with path: data/merged/test.csv | version: merged_v1 | from: ../
2022-05-25 15:42:52,973 - DataLoaderLogger - INFO - DVC: CSV file read with path: data/merged/train.csv | version: merged_v1 | from: ../
2022-05-25 15:42:53,137 - DataLoaderLogger - INFO - DVC: CSV file read with path: data/merged/test.csv | version: merged_v1 | from: ../
2022-05-25 16:10:15,122 - DataLoaderLogger - INFO - DVC: CSV file read with path: data/merged/train.csv | version: merged_v1 | from: ../
2022-05-25 16:10:15,337 - DataLoaderLogger - INFO - DVC: CSV file read with path: data/merged/test.csv | version: merged_v1 | from: ../
2022-05-25 16:32:21,635 - DataLoaderLogger - INFO - DVC: CSV file read with path: data/merged/train.csv | version: merged_v1 | from: ../
2022-05-25 16:32:21,791 - DataLoaderLogger - INFO - DVC: CSV file read with path: data/merged/test.csv | version: merged_v1 | from: ../
2022-05-25 20:06:04,676 - DataLoaderLogger - INFO - DVC: CSV file read with path: data/merged/train.csv | version: merged_v1 | from: ../
2022-05-25 20:06:04,870 - DataLoaderLogger - INFO - DVC: CSV file read with path: data/merged/test.csv | version: merged_v1 | from: ../
2022-05-25 20:07:14,578 - DataLoaderLogger - INFO - DVC: CSV file read with path: data/merged/train.csv | version: merged_v1 | from: ../
2022-05-25 20:07:15,434 - DataLoaderLogger - INFO - DVC: CSV file read with path: data/merged/test.csv | version: merged_v1 | from: ../
2022-05-25 20:12:39,099 - DataLoaderLogger - INFO - DVC: CSV file read with path: data/merged/train.csv | version: merged_v1 | from: ../
2022-05-25 20:12:39,761 - DataLoaderLogger - INFO - DVC: CSV file read with path: data/merged/test.csv | version: merged_v1 | from: ../
2022-05-25 20:14:35,433 - DataLoaderLogger - INFO - DVC: CSV file read with path: data/merged/train.csv | version: merged_v1 | from: ../
2022-05-25 20:14:36,097 - DataLoaderLogger - INFO - DVC: CSV file read with path: data/merged/test.csv | version: merged_v1 | from: ../
2022-05-25 20:33:34,772 - DataLoaderLogger - INFO - DVC: CSV file read with path: data/merged/train.csv | version: merged_v1 | from: ../
2022-05-25 20:33:35,542 - DataLoaderLogger - INFO - DVC: CSV file read with path: data/merged/test.csv | version: merged_v1 | from: ../
2022-05-25 20:59:33,943 - DataLoaderLogger - INFO - DVC: CSV file read with path: data/merged/train.csv | version: merged_v1 | from: ../
2022-05-25 20:59:34,432 - DataLoaderLogger - INFO - DVC: CSV file read with path: data/merged/test.csv | version: merged_v1 | from: ../
2022-05-25 21:07:49,420 - DataLoaderLogger - INFO - DVC: CSV file read with path: data/merged/train.csv | version: merged_v1 | from: ../
2022-05-25 21:07:50,224 - DataLoaderLogger - INFO - DVC: CSV file read with path: data/merged/test.csv | version: merged_v1 | from: ../
2022-05-25 22:24:32,079 - DataLoaderLogger - INFO - DVC: CSV file read with path: data/merged/train.csv | version: merged_v1 | from: ../
2022-05-25 22:24:32,753 - DataLoaderLogger - INFO - DVC: CSV file read with path: data/merged/test.csv | version: merged_v1 | from: ../
2022-05-25 23:04:19,146 - DataLoaderLogger - INFO - DVC: CSV file read with path: data/merged/train.csv | version: merged_v1 | from: ../
2022-05-25 23:04:19,744 - DataLoaderLogger - INFO - DVC: CSV file read with path: data/merged/test.csv | version: merged_v1 | from: ../
2022-05-26 08:02:24,997 - DataLoaderLogger - ERROR - DVC data getter raised an exception
Traceback (most recent call last):
  File "/home/hat/dev-env/10Acadamy/week_3/Rossmann-Pharmaceuticals-Sales-Forcast/venv/lib/python3.10/site-packages/scmrepo/git/backend/dulwich/__init__.py", line 118, in __init__
    self.repo = Repo.discover(start=root_dir)
  File "/home/hat/dev-env/10Acadamy/week_3/Rossmann-Pharmaceuticals-Sales-Forcast/venv/lib/python3.10/site-packages/dulwich/repo.py", line 1184, in discover
    raise NotGitRepository(
dulwich.errors.NotGitRepository: No git repository was found at ../

The above exception was the direct cause of the following exception:

Traceback (most recent call last):
  File "/home/hat/dev-env/10Acadamy/week_3/Rossmann-Pharmaceuticals-Sales-Forcast/venv/lib/python3.10/site-packages/dvc/scm.py", line 55, in map_scm_exception
    yield
  File "/home/hat/dev-env/10Acadamy/week_3/Rossmann-Pharmaceuticals-Sales-Forcast/venv/lib/python3.10/site-packages/dvc/scm.py", line 81, in SCM
    return Git(
  File "/home/hat/dev-env/10Acadamy/week_3/Rossmann-Pharmaceuticals-Sales-Forcast/venv/lib/python3.10/site-packages/scmrepo/git/__init__.py", line 98, in __init__
    first_ = first(self.backends.values())
  File "/home/hat/dev-env/10Acadamy/week_3/Rossmann-Pharmaceuticals-Sales-Forcast/venv/lib/python3.10/site-packages/funcy/seqs.py", line 55, in first
    return next(iter(seq), None)
  File "/usr/lib/python3.10/_collections_abc.py", line 925, in __iter__
    yield self._mapping[key]
  File "/home/hat/dev-env/10Acadamy/week_3/Rossmann-Pharmaceuticals-Sales-Forcast/venv/lib/python3.10/site-packages/scmrepo/git/__init__.py", line 49, in __getitem__
    initialized = backend(*self.args, **self.kwargs)
  File "/home/hat/dev-env/10Acadamy/week_3/Rossmann-Pharmaceuticals-Sales-Forcast/venv/lib/python3.10/site-packages/scmrepo/git/backend/dulwich/__init__.py", line 122, in __init__
    raise SCMError(f"{root_dir} is not a git repository") from exc
scmrepo.exceptions.SCMError: ../ is not a git repository

During handling of the above exception, another exception occurred:

Traceback (most recent call last):
  File "/home/hat/dev-env/10Acadamy/week_3/Rossmann-Pharmaceuticals-Sales-Forcast/src/fetch_data.py", line 25, in dvc_get_data
    content = dvc.api.read(path=path,
  File "/home/hat/dev-env/10Acadamy/week_3/Rossmann-Pharmaceuticals-Sales-Forcast/venv/lib/python3.10/site-packages/dvc/api.py", line 88, in read
    with open(
  File "/usr/lib/python3.10/contextlib.py", line 135, in __enter__
    return next(self.gen)
  File "/home/hat/dev-env/10Acadamy/week_3/Rossmann-Pharmaceuticals-Sales-Forcast/venv/lib/python3.10/site-packages/dvc/api.py", line 75, in _open
    with Repo.open(repo, rev=rev, subrepos=True, uninitialized=True) as _repo:
  File "/home/hat/dev-env/10Acadamy/week_3/Rossmann-Pharmaceuticals-Sales-Forcast/venv/lib/python3.10/site-packages/dvc/repo/__init__.py", line 233, in open
    return Repo(url, *args, **kwargs)
  File "/home/hat/dev-env/10Acadamy/week_3/Rossmann-Pharmaceuticals-Sales-Forcast/venv/lib/python3.10/site-packages/dvc/repo/__init__.py", line 172, in __init__
    self._scm = SCM(root_dir or os.curdir)
  File "/home/hat/dev-env/10Acadamy/week_3/Rossmann-Pharmaceuticals-Sales-Forcast/venv/lib/python3.10/site-packages/dvc/scm.py", line 78, in SCM
    with map_scm_exception():
  File "/usr/lib/python3.10/contextlib.py", line 153, in __exit__
    self.gen.throw(typ, value, traceback)
  File "/home/hat/dev-env/10Acadamy/week_3/Rossmann-Pharmaceuticals-Sales-Forcast/venv/lib/python3.10/site-packages/dvc/scm.py", line 60, in map_scm_exception
    raise into
dvc.scm.SCMError: ../ is not a git repository
2022-05-26 08:02:25,012 - DataLoaderLogger - INFO - Pandas: CSV read from: tests/test_data.csv
2022-05-26 08:03:09,894 - DataLoaderLogger - ERROR - DVC data getter raised an exception
Traceback (most recent call last):
  File "/home/hat/dev-env/10Acadamy/week_3/Rossmann-Pharmaceuticals-Sales-Forcast/venv/lib/python3.10/site-packages/scmrepo/git/backend/dulwich/__init__.py", line 118, in __init__
    self.repo = Repo.discover(start=root_dir)
  File "/home/hat/dev-env/10Acadamy/week_3/Rossmann-Pharmaceuticals-Sales-Forcast/venv/lib/python3.10/site-packages/dulwich/repo.py", line 1184, in discover
    raise NotGitRepository(
dulwich.errors.NotGitRepository: No git repository was found at ../

The above exception was the direct cause of the following exception:

Traceback (most recent call last):
  File "/home/hat/dev-env/10Acadamy/week_3/Rossmann-Pharmaceuticals-Sales-Forcast/venv/lib/python3.10/site-packages/dvc/scm.py", line 55, in map_scm_exception
    yield
  File "/home/hat/dev-env/10Acadamy/week_3/Rossmann-Pharmaceuticals-Sales-Forcast/venv/lib/python3.10/site-packages/dvc/scm.py", line 81, in SCM
    return Git(
  File "/home/hat/dev-env/10Acadamy/week_3/Rossmann-Pharmaceuticals-Sales-Forcast/venv/lib/python3.10/site-packages/scmrepo/git/__init__.py", line 98, in __init__
    first_ = first(self.backends.values())
  File "/home/hat/dev-env/10Acadamy/week_3/Rossmann-Pharmaceuticals-Sales-Forcast/venv/lib/python3.10/site-packages/funcy/seqs.py", line 55, in first
    return next(iter(seq), None)
  File "/usr/lib/python3.10/_collections_abc.py", line 925, in __iter__
    yield self._mapping[key]
  File "/home/hat/dev-env/10Acadamy/week_3/Rossmann-Pharmaceuticals-Sales-Forcast/venv/lib/python3.10/site-packages/scmrepo/git/__init__.py", line 49, in __getitem__
    initialized = backend(*self.args, **self.kwargs)
  File "/home/hat/dev-env/10Acadamy/week_3/Rossmann-Pharmaceuticals-Sales-Forcast/venv/lib/python3.10/site-packages/scmrepo/git/backend/dulwich/__init__.py", line 122, in __init__
    raise SCMError(f"{root_dir} is not a git repository") from exc
scmrepo.exceptions.SCMError: ../ is not a git repository

During handling of the above exception, another exception occurred:

Traceback (most recent call last):
  File "/home/hat/dev-env/10Acadamy/week_3/Rossmann-Pharmaceuticals-Sales-Forcast/src/fetch_data.py", line 25, in dvc_get_data
    content = dvc.api.read(path=path,
  File "/home/hat/dev-env/10Acadamy/week_3/Rossmann-Pharmaceuticals-Sales-Forcast/venv/lib/python3.10/site-packages/dvc/api.py", line 88, in read
    with open(
  File "/usr/lib/python3.10/contextlib.py", line 135, in __enter__
    return next(self.gen)
  File "/home/hat/dev-env/10Acadamy/week_3/Rossmann-Pharmaceuticals-Sales-Forcast/venv/lib/python3.10/site-packages/dvc/api.py", line 75, in _open
    with Repo.open(repo, rev=rev, subrepos=True, uninitialized=True) as _repo:
  File "/home/hat/dev-env/10Acadamy/week_3/Rossmann-Pharmaceuticals-Sales-Forcast/venv/lib/python3.10/site-packages/dvc/repo/__init__.py", line 233, in open
    return Repo(url, *args, **kwargs)
  File "/home/hat/dev-env/10Acadamy/week_3/Rossmann-Pharmaceuticals-Sales-Forcast/venv/lib/python3.10/site-packages/dvc/repo/__init__.py", line 172, in __init__
    self._scm = SCM(root_dir or os.curdir)
  File "/home/hat/dev-env/10Acadamy/week_3/Rossmann-Pharmaceuticals-Sales-Forcast/venv/lib/python3.10/site-packages/dvc/scm.py", line 78, in SCM
    with map_scm_exception():
  File "/usr/lib/python3.10/contextlib.py", line 153, in __exit__
    self.gen.throw(typ, value, traceback)
  File "/home/hat/dev-env/10Acadamy/week_3/Rossmann-Pharmaceuticals-Sales-Forcast/venv/lib/python3.10/site-packages/dvc/scm.py", line 60, in map_scm_exception
    raise into
dvc.scm.SCMError: ../ is not a git repository
2022-05-26 08:03:09,906 - DataLoaderLogger - INFO - Pandas: CSV read from: tests/test_data.csv
2022-05-26 08:04:06,017 - DataLoaderLogger - ERROR - DVC data getter raised an exception
Traceback (most recent call last):
  File "/home/hat/dev-env/10Acadamy/week_3/Rossmann-Pharmaceuticals-Sales-Forcast/venv/lib/python3.10/site-packages/scmrepo/git/backend/dulwich/__init__.py", line 118, in __init__
    self.repo = Repo.discover(start=root_dir)
  File "/home/hat/dev-env/10Acadamy/week_3/Rossmann-Pharmaceuticals-Sales-Forcast/venv/lib/python3.10/site-packages/dulwich/repo.py", line 1184, in discover
    raise NotGitRepository(
dulwich.errors.NotGitRepository: No git repository was found at ../

The above exception was the direct cause of the following exception:

Traceback (most recent call last):
  File "/home/hat/dev-env/10Acadamy/week_3/Rossmann-Pharmaceuticals-Sales-Forcast/venv/lib/python3.10/site-packages/dvc/scm.py", line 55, in map_scm_exception
    yield
  File "/home/hat/dev-env/10Acadamy/week_3/Rossmann-Pharmaceuticals-Sales-Forcast/venv/lib/python3.10/site-packages/dvc/scm.py", line 81, in SCM
    return Git(
  File "/home/hat/dev-env/10Acadamy/week_3/Rossmann-Pharmaceuticals-Sales-Forcast/venv/lib/python3.10/site-packages/scmrepo/git/__init__.py", line 98, in __init__
    first_ = first(self.backends.values())
  File "/home/hat/dev-env/10Acadamy/week_3/Rossmann-Pharmaceuticals-Sales-Forcast/venv/lib/python3.10/site-packages/funcy/seqs.py", line 55, in first
    return next(iter(seq), None)
  File "/usr/lib/python3.10/_collections_abc.py", line 925, in __iter__
    yield self._mapping[key]
  File "/home/hat/dev-env/10Acadamy/week_3/Rossmann-Pharmaceuticals-Sales-Forcast/venv/lib/python3.10/site-packages/scmrepo/git/__init__.py", line 49, in __getitem__
    initialized = backend(*self.args, **self.kwargs)
  File "/home/hat/dev-env/10Acadamy/week_3/Rossmann-Pharmaceuticals-Sales-Forcast/venv/lib/python3.10/site-packages/scmrepo/git/backend/dulwich/__init__.py", line 122, in __init__
    raise SCMError(f"{root_dir} is not a git repository") from exc
scmrepo.exceptions.SCMError: ../ is not a git repository

During handling of the above exception, another exception occurred:

Traceback (most recent call last):
  File "/home/hat/dev-env/10Acadamy/week_3/Rossmann-Pharmaceuticals-Sales-Forcast/src/fetch_data.py", line 25, in dvc_get_data
    content = dvc.api.read(path=path,
  File "/home/hat/dev-env/10Acadamy/week_3/Rossmann-Pharmaceuticals-Sales-Forcast/venv/lib/python3.10/site-packages/dvc/api.py", line 88, in read
    with open(
  File "/usr/lib/python3.10/contextlib.py", line 135, in __enter__
    return next(self.gen)
  File "/home/hat/dev-env/10Acadamy/week_3/Rossmann-Pharmaceuticals-Sales-Forcast/venv/lib/python3.10/site-packages/dvc/api.py", line 75, in _open
    with Repo.open(repo, rev=rev, subrepos=True, uninitialized=True) as _repo:
  File "/home/hat/dev-env/10Acadamy/week_3/Rossmann-Pharmaceuticals-Sales-Forcast/venv/lib/python3.10/site-packages/dvc/repo/__init__.py", line 233, in open
    return Repo(url, *args, **kwargs)
  File "/home/hat/dev-env/10Acadamy/week_3/Rossmann-Pharmaceuticals-Sales-Forcast/venv/lib/python3.10/site-packages/dvc/repo/__init__.py", line 172, in __init__
    self._scm = SCM(root_dir or os.curdir)
  File "/home/hat/dev-env/10Acadamy/week_3/Rossmann-Pharmaceuticals-Sales-Forcast/venv/lib/python3.10/site-packages/dvc/scm.py", line 78, in SCM
    with map_scm_exception():
  File "/usr/lib/python3.10/contextlib.py", line 153, in __exit__
    self.gen.throw(typ, value, traceback)
  File "/home/hat/dev-env/10Acadamy/week_3/Rossmann-Pharmaceuticals-Sales-Forcast/venv/lib/python3.10/site-packages/dvc/scm.py", line 60, in map_scm_exception
    raise into
dvc.scm.SCMError: ../ is not a git repository
2022-05-26 08:04:06,025 - DataLoaderLogger - INFO - Pandas: CSV read from: tests/test_data.csv
2022-05-26 08:05:52,155 - DataLoaderLogger - ERROR - DVC data getter raised an exception
Traceback (most recent call last):
  File "/home/hat/dev-env/10Acadamy/week_3/Rossmann-Pharmaceuticals-Sales-Forcast/venv/lib/python3.10/site-packages/scmrepo/git/backend/dulwich/__init__.py", line 118, in __init__
    self.repo = Repo.discover(start=root_dir)
  File "/home/hat/dev-env/10Acadamy/week_3/Rossmann-Pharmaceuticals-Sales-Forcast/venv/lib/python3.10/site-packages/dulwich/repo.py", line 1184, in discover
    raise NotGitRepository(
dulwich.errors.NotGitRepository: No git repository was found at ../

The above exception was the direct cause of the following exception:

Traceback (most recent call last):
  File "/home/hat/dev-env/10Acadamy/week_3/Rossmann-Pharmaceuticals-Sales-Forcast/venv/lib/python3.10/site-packages/dvc/scm.py", line 55, in map_scm_exception
    yield
  File "/home/hat/dev-env/10Acadamy/week_3/Rossmann-Pharmaceuticals-Sales-Forcast/venv/lib/python3.10/site-packages/dvc/scm.py", line 81, in SCM
    return Git(
  File "/home/hat/dev-env/10Acadamy/week_3/Rossmann-Pharmaceuticals-Sales-Forcast/venv/lib/python3.10/site-packages/scmrepo/git/__init__.py", line 98, in __init__
    first_ = first(self.backends.values())
  File "/home/hat/dev-env/10Acadamy/week_3/Rossmann-Pharmaceuticals-Sales-Forcast/venv/lib/python3.10/site-packages/funcy/seqs.py", line 55, in first
    return next(iter(seq), None)
  File "/usr/lib/python3.10/_collections_abc.py", line 925, in __iter__
    yield self._mapping[key]
  File "/home/hat/dev-env/10Acadamy/week_3/Rossmann-Pharmaceuticals-Sales-Forcast/venv/lib/python3.10/site-packages/scmrepo/git/__init__.py", line 49, in __getitem__
    initialized = backend(*self.args, **self.kwargs)
  File "/home/hat/dev-env/10Acadamy/week_3/Rossmann-Pharmaceuticals-Sales-Forcast/venv/lib/python3.10/site-packages/scmrepo/git/backend/dulwich/__init__.py", line 122, in __init__
    raise SCMError(f"{root_dir} is not a git repository") from exc
scmrepo.exceptions.SCMError: ../ is not a git repository

During handling of the above exception, another exception occurred:

Traceback (most recent call last):
  File "/home/hat/dev-env/10Acadamy/week_3/Rossmann-Pharmaceuticals-Sales-Forcast/src/fetch_data.py", line 25, in dvc_get_data
    content = dvc.api.read(path=path,
  File "/home/hat/dev-env/10Acadamy/week_3/Rossmann-Pharmaceuticals-Sales-Forcast/venv/lib/python3.10/site-packages/dvc/api.py", line 88, in read
    with open(
  File "/usr/lib/python3.10/contextlib.py", line 135, in __enter__
    return next(self.gen)
  File "/home/hat/dev-env/10Acadamy/week_3/Rossmann-Pharmaceuticals-Sales-Forcast/venv/lib/python3.10/site-packages/dvc/api.py", line 75, in _open
    with Repo.open(repo, rev=rev, subrepos=True, uninitialized=True) as _repo:
  File "/home/hat/dev-env/10Acadamy/week_3/Rossmann-Pharmaceuticals-Sales-Forcast/venv/lib/python3.10/site-packages/dvc/repo/__init__.py", line 233, in open
    return Repo(url, *args, **kwargs)
  File "/home/hat/dev-env/10Acadamy/week_3/Rossmann-Pharmaceuticals-Sales-Forcast/venv/lib/python3.10/site-packages/dvc/repo/__init__.py", line 172, in __init__
    self._scm = SCM(root_dir or os.curdir)
  File "/home/hat/dev-env/10Acadamy/week_3/Rossmann-Pharmaceuticals-Sales-Forcast/venv/lib/python3.10/site-packages/dvc/scm.py", line 78, in SCM
    with map_scm_exception():
  File "/usr/lib/python3.10/contextlib.py", line 153, in __exit__
    self.gen.throw(typ, value, traceback)
  File "/home/hat/dev-env/10Acadamy/week_3/Rossmann-Pharmaceuticals-Sales-Forcast/venv/lib/python3.10/site-packages/dvc/scm.py", line 60, in map_scm_exception
    raise into
dvc.scm.SCMError: ../ is not a git repository
2022-05-26 08:05:52,163 - DataLoaderLogger - INFO - Pandas: CSV read from: tests/test_data.csv
2022-05-26 08:06:41,079 - DataLoaderLogger - ERROR - DVC data getter raised an exception
Traceback (most recent call last):
  File "/home/hat/dev-env/10Acadamy/week_3/Rossmann-Pharmaceuticals-Sales-Forcast/venv/lib/python3.10/site-packages/scmrepo/git/backend/dulwich/__init__.py", line 118, in __init__
    self.repo = Repo.discover(start=root_dir)
  File "/home/hat/dev-env/10Acadamy/week_3/Rossmann-Pharmaceuticals-Sales-Forcast/venv/lib/python3.10/site-packages/dulwich/repo.py", line 1184, in discover
    raise NotGitRepository(
dulwich.errors.NotGitRepository: No git repository was found at ../

The above exception was the direct cause of the following exception:

Traceback (most recent call last):
  File "/home/hat/dev-env/10Acadamy/week_3/Rossmann-Pharmaceuticals-Sales-Forcast/venv/lib/python3.10/site-packages/dvc/scm.py", line 55, in map_scm_exception
    yield
  File "/home/hat/dev-env/10Acadamy/week_3/Rossmann-Pharmaceuticals-Sales-Forcast/venv/lib/python3.10/site-packages/dvc/scm.py", line 81, in SCM
    return Git(
  File "/home/hat/dev-env/10Acadamy/week_3/Rossmann-Pharmaceuticals-Sales-Forcast/venv/lib/python3.10/site-packages/scmrepo/git/__init__.py", line 98, in __init__
    first_ = first(self.backends.values())
  File "/home/hat/dev-env/10Acadamy/week_3/Rossmann-Pharmaceuticals-Sales-Forcast/venv/lib/python3.10/site-packages/funcy/seqs.py", line 55, in first
    return next(iter(seq), None)
  File "/usr/lib/python3.10/_collections_abc.py", line 925, in __iter__
    yield self._mapping[key]
  File "/home/hat/dev-env/10Acadamy/week_3/Rossmann-Pharmaceuticals-Sales-Forcast/venv/lib/python3.10/site-packages/scmrepo/git/__init__.py", line 49, in __getitem__
    initialized = backend(*self.args, **self.kwargs)
  File "/home/hat/dev-env/10Acadamy/week_3/Rossmann-Pharmaceuticals-Sales-Forcast/venv/lib/python3.10/site-packages/scmrepo/git/backend/dulwich/__init__.py", line 122, in __init__
    raise SCMError(f"{root_dir} is not a git repository") from exc
scmrepo.exceptions.SCMError: ../ is not a git repository

During handling of the above exception, another exception occurred:

Traceback (most recent call last):
  File "/home/hat/dev-env/10Acadamy/week_3/Rossmann-Pharmaceuticals-Sales-Forcast/src/fetch_data.py", line 25, in dvc_get_data
    content = dvc.api.read(path=path,
  File "/home/hat/dev-env/10Acadamy/week_3/Rossmann-Pharmaceuticals-Sales-Forcast/venv/lib/python3.10/site-packages/dvc/api.py", line 88, in read
    with open(
  File "/usr/lib/python3.10/contextlib.py", line 135, in __enter__
    return next(self.gen)
  File "/home/hat/dev-env/10Acadamy/week_3/Rossmann-Pharmaceuticals-Sales-Forcast/venv/lib/python3.10/site-packages/dvc/api.py", line 75, in _open
    with Repo.open(repo, rev=rev, subrepos=True, uninitialized=True) as _repo:
  File "/home/hat/dev-env/10Acadamy/week_3/Rossmann-Pharmaceuticals-Sales-Forcast/venv/lib/python3.10/site-packages/dvc/repo/__init__.py", line 233, in open
    return Repo(url, *args, **kwargs)
  File "/home/hat/dev-env/10Acadamy/week_3/Rossmann-Pharmaceuticals-Sales-Forcast/venv/lib/python3.10/site-packages/dvc/repo/__init__.py", line 172, in __init__
    self._scm = SCM(root_dir or os.curdir)
  File "/home/hat/dev-env/10Acadamy/week_3/Rossmann-Pharmaceuticals-Sales-Forcast/venv/lib/python3.10/site-packages/dvc/scm.py", line 78, in SCM
    with map_scm_exception():
  File "/usr/lib/python3.10/contextlib.py", line 153, in __exit__
    self.gen.throw(typ, value, traceback)
  File "/home/hat/dev-env/10Acadamy/week_3/Rossmann-Pharmaceuticals-Sales-Forcast/venv/lib/python3.10/site-packages/dvc/scm.py", line 60, in map_scm_exception
    raise into
dvc.scm.SCMError: ../ is not a git repository
2022-05-26 08:06:41,088 - DataLoaderLogger - INFO - Pandas: CSV read from: tests/test_data.csv
2022-05-26 08:07:37,036 - DataLoaderLogger - INFO - DVC: CSV file read with path: data/merged/train.csv | version: merged_v1 | from: ../
2022-05-26 08:07:37,936 - DataLoaderLogger - INFO - DVC: CSV file read with path: data/merged/test.csv | version: merged_v1 | from: ../
2022-05-26 08:07:45,719 - DataLoaderLogger - ERROR - DVC data getter raised an exception
Traceback (most recent call last):
  File "/home/hat/dev-env/10Acadamy/week_3/Rossmann-Pharmaceuticals-Sales-Forcast/venv/lib/python3.10/site-packages/scmrepo/git/backend/dulwich/__init__.py", line 118, in __init__
    self.repo = Repo.discover(start=root_dir)
  File "/home/hat/dev-env/10Acadamy/week_3/Rossmann-Pharmaceuticals-Sales-Forcast/venv/lib/python3.10/site-packages/dulwich/repo.py", line 1184, in discover
    raise NotGitRepository(
dulwich.errors.NotGitRepository: No git repository was found at ../

The above exception was the direct cause of the following exception:

Traceback (most recent call last):
  File "/home/hat/dev-env/10Acadamy/week_3/Rossmann-Pharmaceuticals-Sales-Forcast/venv/lib/python3.10/site-packages/dvc/scm.py", line 55, in map_scm_exception
    yield
  File "/home/hat/dev-env/10Acadamy/week_3/Rossmann-Pharmaceuticals-Sales-Forcast/venv/lib/python3.10/site-packages/dvc/scm.py", line 81, in SCM
    return Git(
  File "/home/hat/dev-env/10Acadamy/week_3/Rossmann-Pharmaceuticals-Sales-Forcast/venv/lib/python3.10/site-packages/scmrepo/git/__init__.py", line 98, in __init__
    first_ = first(self.backends.values())
  File "/home/hat/dev-env/10Acadamy/week_3/Rossmann-Pharmaceuticals-Sales-Forcast/venv/lib/python3.10/site-packages/funcy/seqs.py", line 55, in first
    return next(iter(seq), None)
  File "/usr/lib/python3.10/_collections_abc.py", line 925, in __iter__
    yield self._mapping[key]
  File "/home/hat/dev-env/10Acadamy/week_3/Rossmann-Pharmaceuticals-Sales-Forcast/venv/lib/python3.10/site-packages/scmrepo/git/__init__.py", line 49, in __getitem__
    initialized = backend(*self.args, **self.kwargs)
  File "/home/hat/dev-env/10Acadamy/week_3/Rossmann-Pharmaceuticals-Sales-Forcast/venv/lib/python3.10/site-packages/scmrepo/git/backend/dulwich/__init__.py", line 122, in __init__
    raise SCMError(f"{root_dir} is not a git repository") from exc
scmrepo.exceptions.SCMError: ../ is not a git repository

During handling of the above exception, another exception occurred:

Traceback (most recent call last):
  File "/home/hat/dev-env/10Acadamy/week_3/Rossmann-Pharmaceuticals-Sales-Forcast/src/fetch_data.py", line 25, in dvc_get_data
    content = dvc.api.read(path=path,
  File "/home/hat/dev-env/10Acadamy/week_3/Rossmann-Pharmaceuticals-Sales-Forcast/venv/lib/python3.10/site-packages/dvc/api.py", line 88, in read
    with open(
  File "/usr/lib/python3.10/contextlib.py", line 135, in __enter__
    return next(self.gen)
  File "/home/hat/dev-env/10Acadamy/week_3/Rossmann-Pharmaceuticals-Sales-Forcast/venv/lib/python3.10/site-packages/dvc/api.py", line 75, in _open
    with Repo.open(repo, rev=rev, subrepos=True, uninitialized=True) as _repo:
  File "/home/hat/dev-env/10Acadamy/week_3/Rossmann-Pharmaceuticals-Sales-Forcast/venv/lib/python3.10/site-packages/dvc/repo/__init__.py", line 233, in open
    return Repo(url, *args, **kwargs)
  File "/home/hat/dev-env/10Acadamy/week_3/Rossmann-Pharmaceuticals-Sales-Forcast/venv/lib/python3.10/site-packages/dvc/repo/__init__.py", line 172, in __init__
    self._scm = SCM(root_dir or os.curdir)
  File "/home/hat/dev-env/10Acadamy/week_3/Rossmann-Pharmaceuticals-Sales-Forcast/venv/lib/python3.10/site-packages/dvc/scm.py", line 78, in SCM
    with map_scm_exception():
  File "/usr/lib/python3.10/contextlib.py", line 153, in __exit__
    self.gen.throw(typ, value, traceback)
  File "/home/hat/dev-env/10Acadamy/week_3/Rossmann-Pharmaceuticals-Sales-Forcast/venv/lib/python3.10/site-packages/dvc/scm.py", line 60, in map_scm_exception
    raise into
dvc.scm.SCMError: ../ is not a git repository
2022-05-26 08:07:45,727 - DataLoaderLogger - INFO - Pandas: CSV read from: tests/test_data.csv
2022-05-26 08:08:47,400 - DataLoaderLogger - ERROR - DVC data getter raised an exception
Traceback (most recent call last):
  File "/home/hat/dev-env/10Acadamy/week_3/Rossmann-Pharmaceuticals-Sales-Forcast/venv/lib/python3.10/site-packages/scmrepo/git/backend/dulwich/__init__.py", line 118, in __init__
    self.repo = Repo.discover(start=root_dir)
  File "/home/hat/dev-env/10Acadamy/week_3/Rossmann-Pharmaceuticals-Sales-Forcast/venv/lib/python3.10/site-packages/dulwich/repo.py", line 1184, in discover
    raise NotGitRepository(
dulwich.errors.NotGitRepository: No git repository was found at ../

The above exception was the direct cause of the following exception:

Traceback (most recent call last):
  File "/home/hat/dev-env/10Acadamy/week_3/Rossmann-Pharmaceuticals-Sales-Forcast/venv/lib/python3.10/site-packages/dvc/scm.py", line 55, in map_scm_exception
    yield
  File "/home/hat/dev-env/10Acadamy/week_3/Rossmann-Pharmaceuticals-Sales-Forcast/venv/lib/python3.10/site-packages/dvc/scm.py", line 81, in SCM
    return Git(
  File "/home/hat/dev-env/10Acadamy/week_3/Rossmann-Pharmaceuticals-Sales-Forcast/venv/lib/python3.10/site-packages/scmrepo/git/__init__.py", line 98, in __init__
    first_ = first(self.backends.values())
  File "/home/hat/dev-env/10Acadamy/week_3/Rossmann-Pharmaceuticals-Sales-Forcast/venv/lib/python3.10/site-packages/funcy/seqs.py", line 55, in first
    return next(iter(seq), None)
  File "/usr/lib/python3.10/_collections_abc.py", line 925, in __iter__
    yield self._mapping[key]
  File "/home/hat/dev-env/10Acadamy/week_3/Rossmann-Pharmaceuticals-Sales-Forcast/venv/lib/python3.10/site-packages/scmrepo/git/__init__.py", line 49, in __getitem__
    initialized = backend(*self.args, **self.kwargs)
  File "/home/hat/dev-env/10Acadamy/week_3/Rossmann-Pharmaceuticals-Sales-Forcast/venv/lib/python3.10/site-packages/scmrepo/git/backend/dulwich/__init__.py", line 122, in __init__
    raise SCMError(f"{root_dir} is not a git repository") from exc
scmrepo.exceptions.SCMError: ../ is not a git repository

During handling of the above exception, another exception occurred:

Traceback (most recent call last):
  File "/home/hat/dev-env/10Acadamy/week_3/Rossmann-Pharmaceuticals-Sales-Forcast/src/fetch_data.py", line 25, in dvc_get_data
    content = dvc.api.read(path=path,
  File "/home/hat/dev-env/10Acadamy/week_3/Rossmann-Pharmaceuticals-Sales-Forcast/venv/lib/python3.10/site-packages/dvc/api.py", line 88, in read
    with open(
  File "/usr/lib/python3.10/contextlib.py", line 135, in __enter__
    return next(self.gen)
  File "/home/hat/dev-env/10Acadamy/week_3/Rossmann-Pharmaceuticals-Sales-Forcast/venv/lib/python3.10/site-packages/dvc/api.py", line 75, in _open
    with Repo.open(repo, rev=rev, subrepos=True, uninitialized=True) as _repo:
  File "/home/hat/dev-env/10Acadamy/week_3/Rossmann-Pharmaceuticals-Sales-Forcast/venv/lib/python3.10/site-packages/dvc/repo/__init__.py", line 233, in open
    return Repo(url, *args, **kwargs)
  File "/home/hat/dev-env/10Acadamy/week_3/Rossmann-Pharmaceuticals-Sales-Forcast/venv/lib/python3.10/site-packages/dvc/repo/__init__.py", line 172, in __init__
    self._scm = SCM(root_dir or os.curdir)
  File "/home/hat/dev-env/10Acadamy/week_3/Rossmann-Pharmaceuticals-Sales-Forcast/venv/lib/python3.10/site-packages/dvc/scm.py", line 78, in SCM
    with map_scm_exception():
  File "/usr/lib/python3.10/contextlib.py", line 153, in __exit__
    self.gen.throw(typ, value, traceback)
  File "/home/hat/dev-env/10Acadamy/week_3/Rossmann-Pharmaceuticals-Sales-Forcast/venv/lib/python3.10/site-packages/dvc/scm.py", line 60, in map_scm_exception
    raise into
dvc.scm.SCMError: ../ is not a git repository
2022-05-26 08:08:47,408 - DataLoaderLogger - INFO - Pandas: CSV read from: tests/test_data.csv
2022-05-26 08:12:18,888 - DataLoaderLogger - ERROR - DVC data getter raised an exception
Traceback (most recent call last):
  File "/home/hat/dev-env/10Acadamy/week_3/Rossmann-Pharmaceuticals-Sales-Forcast/venv/lib/python3.10/site-packages/scmrepo/git/backend/dulwich/__init__.py", line 118, in __init__
    self.repo = Repo.discover(start=root_dir)
  File "/home/hat/dev-env/10Acadamy/week_3/Rossmann-Pharmaceuticals-Sales-Forcast/venv/lib/python3.10/site-packages/dulwich/repo.py", line 1184, in discover
    raise NotGitRepository(
dulwich.errors.NotGitRepository: No git repository was found at ../

The above exception was the direct cause of the following exception:

Traceback (most recent call last):
  File "/home/hat/dev-env/10Acadamy/week_3/Rossmann-Pharmaceuticals-Sales-Forcast/venv/lib/python3.10/site-packages/dvc/scm.py", line 55, in map_scm_exception
    yield
  File "/home/hat/dev-env/10Acadamy/week_3/Rossmann-Pharmaceuticals-Sales-Forcast/venv/lib/python3.10/site-packages/dvc/scm.py", line 81, in SCM
    return Git(
  File "/home/hat/dev-env/10Acadamy/week_3/Rossmann-Pharmaceuticals-Sales-Forcast/venv/lib/python3.10/site-packages/scmrepo/git/__init__.py", line 98, in __init__
    first_ = first(self.backends.values())
  File "/home/hat/dev-env/10Acadamy/week_3/Rossmann-Pharmaceuticals-Sales-Forcast/venv/lib/python3.10/site-packages/funcy/seqs.py", line 55, in first
    return next(iter(seq), None)
  File "/usr/lib/python3.10/_collections_abc.py", line 925, in __iter__
    yield self._mapping[key]
  File "/home/hat/dev-env/10Acadamy/week_3/Rossmann-Pharmaceuticals-Sales-Forcast/venv/lib/python3.10/site-packages/scmrepo/git/__init__.py", line 49, in __getitem__
    initialized = backend(*self.args, **self.kwargs)
  File "/home/hat/dev-env/10Acadamy/week_3/Rossmann-Pharmaceuticals-Sales-Forcast/venv/lib/python3.10/site-packages/scmrepo/git/backend/dulwich/__init__.py", line 122, in __init__
    raise SCMError(f"{root_dir} is not a git repository") from exc
scmrepo.exceptions.SCMError: ../ is not a git repository

During handling of the above exception, another exception occurred:

Traceback (most recent call last):
  File "/home/hat/dev-env/10Acadamy/week_3/Rossmann-Pharmaceuticals-Sales-Forcast/src/fetch_data.py", line 25, in dvc_get_data
    content = dvc.api.read(path=path,
  File "/home/hat/dev-env/10Acadamy/week_3/Rossmann-Pharmaceuticals-Sales-Forcast/venv/lib/python3.10/site-packages/dvc/api.py", line 88, in read
    with open(
  File "/usr/lib/python3.10/contextlib.py", line 135, in __enter__
    return next(self.gen)
  File "/home/hat/dev-env/10Acadamy/week_3/Rossmann-Pharmaceuticals-Sales-Forcast/venv/lib/python3.10/site-packages/dvc/api.py", line 75, in _open
    with Repo.open(repo, rev=rev, subrepos=True, uninitialized=True) as _repo:
  File "/home/hat/dev-env/10Acadamy/week_3/Rossmann-Pharmaceuticals-Sales-Forcast/venv/lib/python3.10/site-packages/dvc/repo/__init__.py", line 233, in open
    return Repo(url, *args, **kwargs)
  File "/home/hat/dev-env/10Acadamy/week_3/Rossmann-Pharmaceuticals-Sales-Forcast/venv/lib/python3.10/site-packages/dvc/repo/__init__.py", line 172, in __init__
    self._scm = SCM(root_dir or os.curdir)
  File "/home/hat/dev-env/10Acadamy/week_3/Rossmann-Pharmaceuticals-Sales-Forcast/venv/lib/python3.10/site-packages/dvc/scm.py", line 78, in SCM
    with map_scm_exception():
  File "/usr/lib/python3.10/contextlib.py", line 153, in __exit__
    self.gen.throw(typ, value, traceback)
  File "/home/hat/dev-env/10Acadamy/week_3/Rossmann-Pharmaceuticals-Sales-Forcast/venv/lib/python3.10/site-packages/dvc/scm.py", line 60, in map_scm_exception
    raise into
dvc.scm.SCMError: ../ is not a git repository
2022-05-26 08:12:18,896 - DataLoaderLogger - INFO - Pandas: CSV read from: tests/test_data.csv
2022-05-26 08:13:19,863 - DataLoaderLogger - INFO - DVC: CSV file read with path: data/merged/test.csv | version: merged_v1 | from: ../
2022-05-26 08:13:19,909 - DataLoaderLogger - ERROR - Pandas failed to read the csv at: tests/test_data.csv
Traceback (most recent call last):
  File "/home/hat/dev-env/10Acadamy/week_3/Rossmann-Pharmaceuticals-Sales-Forcast/tests/../src/fetch_data.py", line 38, in read_csv
    df = pd.read_csv(path)
  File "/home/hat/dev-env/10Acadamy/week_3/Rossmann-Pharmaceuticals-Sales-Forcast/venv/lib/python3.10/site-packages/pandas/util/_decorators.py", line 311, in wrapper
    return func(*args, **kwargs)
  File "/home/hat/dev-env/10Acadamy/week_3/Rossmann-Pharmaceuticals-Sales-Forcast/venv/lib/python3.10/site-packages/pandas/io/parsers/readers.py", line 680, in read_csv
    return _read(filepath_or_buffer, kwds)
  File "/home/hat/dev-env/10Acadamy/week_3/Rossmann-Pharmaceuticals-Sales-Forcast/venv/lib/python3.10/site-packages/pandas/io/parsers/readers.py", line 575, in _read
    parser = TextFileReader(filepath_or_buffer, **kwds)
  File "/home/hat/dev-env/10Acadamy/week_3/Rossmann-Pharmaceuticals-Sales-Forcast/venv/lib/python3.10/site-packages/pandas/io/parsers/readers.py", line 933, in __init__
    self._engine = self._make_engine(f, self.engine)
  File "/home/hat/dev-env/10Acadamy/week_3/Rossmann-Pharmaceuticals-Sales-Forcast/venv/lib/python3.10/site-packages/pandas/io/parsers/readers.py", line 1217, in _make_engine
    self.handles = get_handle(  # type: ignore[call-overload]
  File "/home/hat/dev-env/10Acadamy/week_3/Rossmann-Pharmaceuticals-Sales-Forcast/venv/lib/python3.10/site-packages/pandas/io/common.py", line 789, in get_handle
    handle = open(
FileNotFoundError: [Errno 2] No such file or directory: 'tests/test_data.csv'
2022-05-26 08:13:55,153 - DataLoaderLogger - INFO - DVC: CSV file read with path: data/merged/test.csv | version: merged_v1 | from: ../
2022-05-26 08:13:55,216 - DataLoaderLogger - ERROR - Pandas failed to read the csv at: tests/test_data.csv
Traceback (most recent call last):
  File "/home/hat/dev-env/10Acadamy/week_3/Rossmann-Pharmaceuticals-Sales-Forcast/tests/../src/fetch_data.py", line 38, in read_csv
    df = pd.read_csv(path)
  File "/home/hat/dev-env/10Acadamy/week_3/Rossmann-Pharmaceuticals-Sales-Forcast/venv/lib/python3.10/site-packages/pandas/util/_decorators.py", line 311, in wrapper
    return func(*args, **kwargs)
  File "/home/hat/dev-env/10Acadamy/week_3/Rossmann-Pharmaceuticals-Sales-Forcast/venv/lib/python3.10/site-packages/pandas/io/parsers/readers.py", line 680, in read_csv
    return _read(filepath_or_buffer, kwds)
  File "/home/hat/dev-env/10Acadamy/week_3/Rossmann-Pharmaceuticals-Sales-Forcast/venv/lib/python3.10/site-packages/pandas/io/parsers/readers.py", line 575, in _read
    parser = TextFileReader(filepath_or_buffer, **kwds)
  File "/home/hat/dev-env/10Acadamy/week_3/Rossmann-Pharmaceuticals-Sales-Forcast/venv/lib/python3.10/site-packages/pandas/io/parsers/readers.py", line 933, in __init__
    self._engine = self._make_engine(f, self.engine)
  File "/home/hat/dev-env/10Acadamy/week_3/Rossmann-Pharmaceuticals-Sales-Forcast/venv/lib/python3.10/site-packages/pandas/io/parsers/readers.py", line 1217, in _make_engine
    self.handles = get_handle(  # type: ignore[call-overload]
  File "/home/hat/dev-env/10Acadamy/week_3/Rossmann-Pharmaceuticals-Sales-Forcast/venv/lib/python3.10/site-packages/pandas/io/common.py", line 789, in get_handle
    handle = open(
FileNotFoundError: [Errno 2] No such file or directory: 'tests/test_data.csv'
2022-05-26 08:14:17,176 - DataLoaderLogger - ERROR - DVC data getter raised an exception
Traceback (most recent call last):
  File "/home/hat/dev-env/10Acadamy/week_3/Rossmann-Pharmaceuticals-Sales-Forcast/venv/lib/python3.10/site-packages/dvc/fs/dvc.py", line 114, in info
    outs = list(self.repo.index.tree.iteritems(key))
  File "/home/hat/dev-env/10Acadamy/week_3/Rossmann-Pharmaceuticals-Sales-Forcast/venv/lib/python3.10/site-packages/dvc/data/tree.py", line 92, in iteritems
    for key, (meta, hash_info) in self._trie.iteritems(**kwargs):
  File "/home/hat/dev-env/10Acadamy/week_3/Rossmann-Pharmaceuticals-Sales-Forcast/venv/lib/python3.10/site-packages/pygtrie.py", line 633, in iteritems
    node, _ = self._get_node(prefix)
  File "/home/hat/dev-env/10Acadamy/week_3/Rossmann-Pharmaceuticals-Sales-Forcast/venv/lib/python3.10/site-packages/pygtrie.py", line 545, in _get_node
    raise KeyError(key)
KeyError: ('repo', 'data', 'merged', 'test.csv')

The above exception was the direct cause of the following exception:

Traceback (most recent call last):
  File "/home/hat/dev-env/10Acadamy/week_3/Rossmann-Pharmaceuticals-Sales-Forcast/venv/lib/python3.10/site-packages/dvc/repo/__init__.py", line 498, in open_by_relpath
    with fs.open(
  File "/home/hat/dev-env/10Acadamy/week_3/Rossmann-Pharmaceuticals-Sales-Forcast/venv/lib/python3.10/site-packages/dvc/fs/base.py", line 186, in open
    return self.fs.open(path, mode=mode, encoding=encoding, **kwargs)
  File "/home/hat/dev-env/10Acadamy/week_3/Rossmann-Pharmaceuticals-Sales-Forcast/venv/lib/python3.10/site-packages/dvc/fs/repo.py", line 309, in open
    return dvc_fs.open(dvc_path, mode=mode, encoding=encoding, **kwargs)
  File "/home/hat/dev-env/10Acadamy/week_3/Rossmann-Pharmaceuticals-Sales-Forcast/venv/lib/python3.10/site-packages/dvc/fs/base.py", line 186, in open
    return self.fs.open(path, mode=mode, encoding=encoding, **kwargs)
  File "/home/hat/dev-env/10Acadamy/week_3/Rossmann-Pharmaceuticals-Sales-Forcast/venv/lib/python3.10/site-packages/dvc/fs/dvc.py", line 77, in open
    fs, fspath = self._get_fs_path(path, **kwargs)
  File "/home/hat/dev-env/10Acadamy/week_3/Rossmann-Pharmaceuticals-Sales-Forcast/venv/lib/python3.10/site-packages/dvc/fs/dvc.py", line 54, in _get_fs_path
    info = self.info(path)
  File "/home/hat/dev-env/10Acadamy/week_3/Rossmann-Pharmaceuticals-Sales-Forcast/venv/lib/python3.10/site-packages/dvc/fs/dvc.py", line 116, in info
    raise FileNotFoundError from exc
FileNotFoundError

The above exception was the direct cause of the following exception:

Traceback (most recent call last):
  File "/home/hat/dev-env/10Acadamy/week_3/Rossmann-Pharmaceuticals-Sales-Forcast/tests/../src/fetch_data.py", line 25, in dvc_get_data
    content = dvc.api.read(path=path,
  File "/home/hat/dev-env/10Acadamy/week_3/Rossmann-Pharmaceuticals-Sales-Forcast/venv/lib/python3.10/site-packages/dvc/api.py", line 88, in read
    with open(
  File "/usr/lib/python3.10/contextlib.py", line 135, in __enter__
    return next(self.gen)
  File "/home/hat/dev-env/10Acadamy/week_3/Rossmann-Pharmaceuticals-Sales-Forcast/venv/lib/python3.10/site-packages/dvc/api.py", line 76, in _open
    with _repo.open_by_relpath(
  File "/usr/lib/python3.10/contextlib.py", line 135, in __enter__
    return next(self.gen)
  File "/home/hat/dev-env/10Acadamy/week_3/Rossmann-Pharmaceuticals-Sales-Forcast/venv/lib/python3.10/site-packages/dvc/repo/__init__.py", line 503, in open_by_relpath
    raise FileMissingError(path) from exc
dvc.exceptions.FileMissingError: Can't find 'data/merged/test.csv' neither locally nor on remote
2022-05-26 08:14:17,183 - DataLoaderLogger - ERROR - Pandas failed to read the csv at: tests/test_data.csv
Traceback (most recent call last):
  File "/home/hat/dev-env/10Acadamy/week_3/Rossmann-Pharmaceuticals-Sales-Forcast/tests/../src/fetch_data.py", line 38, in read_csv
    df = pd.read_csv(path)
  File "/home/hat/dev-env/10Acadamy/week_3/Rossmann-Pharmaceuticals-Sales-Forcast/venv/lib/python3.10/site-packages/pandas/util/_decorators.py", line 311, in wrapper
    return func(*args, **kwargs)
  File "/home/hat/dev-env/10Acadamy/week_3/Rossmann-Pharmaceuticals-Sales-Forcast/venv/lib/python3.10/site-packages/pandas/io/parsers/readers.py", line 680, in read_csv
    return _read(filepath_or_buffer, kwds)
  File "/home/hat/dev-env/10Acadamy/week_3/Rossmann-Pharmaceuticals-Sales-Forcast/venv/lib/python3.10/site-packages/pandas/io/parsers/readers.py", line 575, in _read
    parser = TextFileReader(filepath_or_buffer, **kwds)
  File "/home/hat/dev-env/10Acadamy/week_3/Rossmann-Pharmaceuticals-Sales-Forcast/venv/lib/python3.10/site-packages/pandas/io/parsers/readers.py", line 933, in __init__
    self._engine = self._make_engine(f, self.engine)
  File "/home/hat/dev-env/10Acadamy/week_3/Rossmann-Pharmaceuticals-Sales-Forcast/venv/lib/python3.10/site-packages/pandas/io/parsers/readers.py", line 1217, in _make_engine
    self.handles = get_handle(  # type: ignore[call-overload]
  File "/home/hat/dev-env/10Acadamy/week_3/Rossmann-Pharmaceuticals-Sales-Forcast/venv/lib/python3.10/site-packages/pandas/io/common.py", line 789, in get_handle
    handle = open(
FileNotFoundError: [Errno 2] No such file or directory: 'tests/test_data.csv'
2022-05-26 08:14:56,126 - DataLoaderLogger - ERROR - DVC data getter raised an exception
Traceback (most recent call last):
  File "/home/hat/dev-env/10Acadamy/week_3/Rossmann-Pharmaceuticals-Sales-Forcast/venv/lib/python3.10/site-packages/dvc/fs/dvc.py", line 114, in info
    outs = list(self.repo.index.tree.iteritems(key))
  File "/home/hat/dev-env/10Acadamy/week_3/Rossmann-Pharmaceuticals-Sales-Forcast/venv/lib/python3.10/site-packages/dvc/data/tree.py", line 92, in iteritems
    for key, (meta, hash_info) in self._trie.iteritems(**kwargs):
  File "/home/hat/dev-env/10Acadamy/week_3/Rossmann-Pharmaceuticals-Sales-Forcast/venv/lib/python3.10/site-packages/pygtrie.py", line 633, in iteritems
    node, _ = self._get_node(prefix)
  File "/home/hat/dev-env/10Acadamy/week_3/Rossmann-Pharmaceuticals-Sales-Forcast/venv/lib/python3.10/site-packages/pygtrie.py", line 545, in _get_node
    raise KeyError(key)
KeyError: ('repo', 'data', 'merged', 'test.csv')

The above exception was the direct cause of the following exception:

Traceback (most recent call last):
  File "/home/hat/dev-env/10Acadamy/week_3/Rossmann-Pharmaceuticals-Sales-Forcast/venv/lib/python3.10/site-packages/dvc/repo/__init__.py", line 498, in open_by_relpath
    with fs.open(
  File "/home/hat/dev-env/10Acadamy/week_3/Rossmann-Pharmaceuticals-Sales-Forcast/venv/lib/python3.10/site-packages/dvc/fs/base.py", line 186, in open
    return self.fs.open(path, mode=mode, encoding=encoding, **kwargs)
  File "/home/hat/dev-env/10Acadamy/week_3/Rossmann-Pharmaceuticals-Sales-Forcast/venv/lib/python3.10/site-packages/dvc/fs/repo.py", line 309, in open
    return dvc_fs.open(dvc_path, mode=mode, encoding=encoding, **kwargs)
  File "/home/hat/dev-env/10Acadamy/week_3/Rossmann-Pharmaceuticals-Sales-Forcast/venv/lib/python3.10/site-packages/dvc/fs/base.py", line 186, in open
    return self.fs.open(path, mode=mode, encoding=encoding, **kwargs)
  File "/home/hat/dev-env/10Acadamy/week_3/Rossmann-Pharmaceuticals-Sales-Forcast/venv/lib/python3.10/site-packages/dvc/fs/dvc.py", line 77, in open
    fs, fspath = self._get_fs_path(path, **kwargs)
  File "/home/hat/dev-env/10Acadamy/week_3/Rossmann-Pharmaceuticals-Sales-Forcast/venv/lib/python3.10/site-packages/dvc/fs/dvc.py", line 54, in _get_fs_path
    info = self.info(path)
  File "/home/hat/dev-env/10Acadamy/week_3/Rossmann-Pharmaceuticals-Sales-Forcast/venv/lib/python3.10/site-packages/dvc/fs/dvc.py", line 116, in info
    raise FileNotFoundError from exc
FileNotFoundError

The above exception was the direct cause of the following exception:

Traceback (most recent call last):
  File "/home/hat/dev-env/10Acadamy/week_3/Rossmann-Pharmaceuticals-Sales-Forcast/tests/../src/fetch_data.py", line 25, in dvc_get_data
    content = dvc.api.read(path=path,
  File "/home/hat/dev-env/10Acadamy/week_3/Rossmann-Pharmaceuticals-Sales-Forcast/venv/lib/python3.10/site-packages/dvc/api.py", line 88, in read
    with open(
  File "/usr/lib/python3.10/contextlib.py", line 135, in __enter__
    return next(self.gen)
  File "/home/hat/dev-env/10Acadamy/week_3/Rossmann-Pharmaceuticals-Sales-Forcast/venv/lib/python3.10/site-packages/dvc/api.py", line 76, in _open
    with _repo.open_by_relpath(
  File "/usr/lib/python3.10/contextlib.py", line 135, in __enter__
    return next(self.gen)
  File "/home/hat/dev-env/10Acadamy/week_3/Rossmann-Pharmaceuticals-Sales-Forcast/venv/lib/python3.10/site-packages/dvc/repo/__init__.py", line 503, in open_by_relpath
    raise FileMissingError(path) from exc
dvc.exceptions.FileMissingError: Can't find 'data/merged/test.csv' neither locally nor on remote
2022-05-26 08:14:56,137 - DataLoaderLogger - INFO - Pandas: CSV read from: ./test_data.csv
2022-05-26 08:15:12,173 - DataLoaderLogger - INFO - DVC: CSV file read with path: data/raw/test.csv | version: raw_data | from: ../
2022-05-26 08:15:12,207 - DataLoaderLogger - INFO - Pandas: CSV read from: ./test_data.csv
2022-05-26 08:15:51,236 - DataLoaderLogger - INFO - DVC: CSV file read with path: data/raw/test.csv | version: raw_data | from: ../
2022-05-26 08:15:51,264 - DataLoaderLogger - INFO - Pandas: CSV read from: ./test_data.csv
2022-05-26 08:16:25,766 - DataLoaderLogger - ERROR - DVC data getter raised an exception
Traceback (most recent call last):
  File "/home/hat/dev-env/10Acadamy/week_3/Rossmann-Pharmaceuticals-Sales-Forcast/venv/lib/python3.10/site-packages/scmrepo/git/backend/dulwich/__init__.py", line 118, in __init__
    self.repo = Repo.discover(start=root_dir)
  File "/home/hat/dev-env/10Acadamy/week_3/Rossmann-Pharmaceuticals-Sales-Forcast/venv/lib/python3.10/site-packages/dulwich/repo.py", line 1184, in discover
    raise NotGitRepository(
dulwich.errors.NotGitRepository: No git repository was found at ../

The above exception was the direct cause of the following exception:

Traceback (most recent call last):
  File "/home/hat/dev-env/10Acadamy/week_3/Rossmann-Pharmaceuticals-Sales-Forcast/venv/lib/python3.10/site-packages/dvc/scm.py", line 55, in map_scm_exception
    yield
  File "/home/hat/dev-env/10Acadamy/week_3/Rossmann-Pharmaceuticals-Sales-Forcast/venv/lib/python3.10/site-packages/dvc/scm.py", line 81, in SCM
    return Git(
  File "/home/hat/dev-env/10Acadamy/week_3/Rossmann-Pharmaceuticals-Sales-Forcast/venv/lib/python3.10/site-packages/scmrepo/git/__init__.py", line 98, in __init__
    first_ = first(self.backends.values())
  File "/home/hat/dev-env/10Acadamy/week_3/Rossmann-Pharmaceuticals-Sales-Forcast/venv/lib/python3.10/site-packages/funcy/seqs.py", line 55, in first
    return next(iter(seq), None)
  File "/usr/lib/python3.10/_collections_abc.py", line 925, in __iter__
    yield self._mapping[key]
  File "/home/hat/dev-env/10Acadamy/week_3/Rossmann-Pharmaceuticals-Sales-Forcast/venv/lib/python3.10/site-packages/scmrepo/git/__init__.py", line 49, in __getitem__
    initialized = backend(*self.args, **self.kwargs)
  File "/home/hat/dev-env/10Acadamy/week_3/Rossmann-Pharmaceuticals-Sales-Forcast/venv/lib/python3.10/site-packages/scmrepo/git/backend/dulwich/__init__.py", line 122, in __init__
    raise SCMError(f"{root_dir} is not a git repository") from exc
scmrepo.exceptions.SCMError: ../ is not a git repository

During handling of the above exception, another exception occurred:

Traceback (most recent call last):
  File "/home/hat/dev-env/10Acadamy/week_3/Rossmann-Pharmaceuticals-Sales-Forcast/src/fetch_data.py", line 25, in dvc_get_data
    content = dvc.api.read(path=path,
  File "/home/hat/dev-env/10Acadamy/week_3/Rossmann-Pharmaceuticals-Sales-Forcast/venv/lib/python3.10/site-packages/dvc/api.py", line 88, in read
    with open(
  File "/usr/lib/python3.10/contextlib.py", line 135, in __enter__
    return next(self.gen)
  File "/home/hat/dev-env/10Acadamy/week_3/Rossmann-Pharmaceuticals-Sales-Forcast/venv/lib/python3.10/site-packages/dvc/api.py", line 75, in _open
    with Repo.open(repo, rev=rev, subrepos=True, uninitialized=True) as _repo:
  File "/home/hat/dev-env/10Acadamy/week_3/Rossmann-Pharmaceuticals-Sales-Forcast/venv/lib/python3.10/site-packages/dvc/repo/__init__.py", line 233, in open
    return Repo(url, *args, **kwargs)
  File "/home/hat/dev-env/10Acadamy/week_3/Rossmann-Pharmaceuticals-Sales-Forcast/venv/lib/python3.10/site-packages/dvc/repo/__init__.py", line 172, in __init__
    self._scm = SCM(root_dir or os.curdir)
  File "/home/hat/dev-env/10Acadamy/week_3/Rossmann-Pharmaceuticals-Sales-Forcast/venv/lib/python3.10/site-packages/dvc/scm.py", line 78, in SCM
    with map_scm_exception():
  File "/usr/lib/python3.10/contextlib.py", line 153, in __exit__
    self.gen.throw(typ, value, traceback)
  File "/home/hat/dev-env/10Acadamy/week_3/Rossmann-Pharmaceuticals-Sales-Forcast/venv/lib/python3.10/site-packages/dvc/scm.py", line 60, in map_scm_exception
    raise into
dvc.scm.SCMError: ../ is not a git repository
2022-05-26 08:16:25,779 - DataLoaderLogger - INFO - Pandas: CSV read from: tests/test_data.csv
2022-05-26 08:16:42,654 - DataLoaderLogger - INFO - DVC: CSV file read with path: data/raw/test.csv | version: raw_data | from: ./
2022-05-26 08:16:42,660 - DataLoaderLogger - INFO - Pandas: CSV read from: tests/test_data.csv
2022-05-26 08:57:46,270 - DataLoaderLogger - INFO - DVC: CSV file read with path: data/raw/test.csv | version: raw_data | from: ./
2022-05-26 08:57:46,277 - DataLoaderLogger - INFO - Pandas: CSV read from: tests/test_data.csv
2022-05-26 08:58:08,765 - DataLoaderLogger - INFO - DVC: CSV file read with path: data/raw/test.csv | version: raw_data | from: ./
2022-05-26 08:58:08,772 - DataLoaderLogger - INFO - Pandas: CSV read from: tests/test_data.csv
2022-05-26 10:00:47,676 - DataLoaderLogger - INFO - DVC: CSV file read with path: data/merged/train.csv | version: merged_v1 | from: ../
2022-05-26 10:00:48,370 - DataLoaderLogger - INFO - DVC: CSV file read with path: data/merged/test.csv | version: merged_v1 | from: ../
2022-05-26 10:06:26,233 - DataLoaderLogger - INFO - DVC: CSV file read with path: data/merged/train.csv | version: merged_v1 | from: ../
2022-05-26 10:06:26,862 - DataLoaderLogger - INFO - DVC: CSV file read with path: data/merged/test.csv | version: merged_v1 | from: ../
2022-05-26 14:17:55,709 - DataLoaderLogger - INFO - DVC: CSV file read with path: data/merged/train.csv | version: merged_v1 | from: ../
2022-05-26 14:17:56,454 - DataLoaderLogger - INFO - DVC: CSV file read with path: data/merged/test.csv | version: merged_v1 | from: ../
2022-05-26 14:19:02,776 - DataLoaderLogger - INFO - DVC: CSV file read with path: data/merged/train.csv | version: merged_v1 | from: ../
2022-05-26 14:19:03,853 - DataLoaderLogger - INFO - DVC: CSV file read with path: data/merged/test.csv | version: merged_v1 | from: ../
2022-05-26 14:22:35,765 - DataLoaderLogger - INFO - DVC: CSV file read with path: data/merged/train.csv | version: merged_v1 | from: ../
2022-05-26 14:22:36,523 - DataLoaderLogger - INFO - DVC: CSV file read with path: data/merged/test.csv | version: merged_v1 | from: ../
2022-05-26 14:24:20,883 - DataLoaderLogger - INFO - DVC: CSV file read with path: data/merged/train.csv | version: merged_v1 | from: ../
2022-05-26 14:24:21,565 - DataLoaderLogger - INFO - DVC: CSV file read with path: data/merged/test.csv | version: merged_v1 | from: ../
2022-05-26 14:25:27,327 - DataLoaderLogger - INFO - DVC: CSV file read with path: data/merged/train.csv | version: merged_v1 | from: ../
2022-05-26 14:25:27,970 - DataLoaderLogger - INFO - DVC: CSV file read with path: data/merged/test.csv | version: merged_v1 | from: ../
2022-05-26 14:27:20,916 - DataLoaderLogger - INFO - DVC: CSV file read with path: data/merged/train.csv | version: merged_v1 | from: ../
2022-05-26 14:27:21,630 - DataLoaderLogger - INFO - DVC: CSV file read with path: data/merged/test.csv | version: merged_v1 | from: ../
2022-05-26 14:29:25,665 - DataLoaderLogger - INFO - DVC: CSV file read with path: data/merged/train.csv | version: merged_v1 | from: ../
2022-05-26 14:29:26,439 - DataLoaderLogger - INFO - DVC: CSV file read with path: data/merged/test.csv | version: merged_v1 | from: ../
2022-05-26 16:07:35,590 - DataLoaderLogger - INFO - DVC: CSV file read with path: data/merged/train.csv | version: merged_v1 | from: ../
2022-05-26 16:07:36,213 - DataLoaderLogger - INFO - DVC: CSV file read with path: data/merged/test.csv | version: merged_v1 | from: ../
2022-05-26 17:23:38,814 - DataLoaderLogger - INFO - DVC: CSV file read with path: data/merged/train.csv | version: merged_v1 | from: ../
2022-05-26 17:23:40,862 - DataLoaderLogger - INFO - DVC: CSV file read with path: data/merged/test.csv | version: merged_v1 | from: ../
2022-05-26 17:26:07,945 - DataLoaderLogger - INFO - DVC: CSV file read with path: data/merged/train.csv | version: merged_v1 | from: ../
2022-05-26 17:26:10,066 - DataLoaderLogger - INFO - DVC: CSV file read with path: data/merged/test.csv | version: merged_v1 | from: ../
2022-05-26 17:31:28,144 - DataLoaderLogger - INFO - DVC: CSV file read with path: data/merged/train.csv | version: merged_v1 | from: ../
2022-05-26 17:31:29,087 - DataLoaderLogger - INFO - DVC: CSV file read with path: data/merged/test.csv | version: merged_v1 | from: ../
2022-05-26 17:58:23,994 - DataLoaderLogger - INFO - DVC: CSV file read with path: data/merged/train.csv | version: merged_v1 | from: ../
2022-05-26 17:58:24,695 - DataLoaderLogger - INFO - DVC: CSV file read with path: data/merged/test.csv | version: merged_v1 | from: ../
2022-05-26 18:00:56,785 - DataLoaderLogger - INFO - DVC: CSV file read with path: data/merged/train.csv | version: merged_v1 | from: ../
2022-05-26 18:00:57,771 - DataLoaderLogger - INFO - DVC: CSV file read with path: data/merged/test.csv | version: merged_v1 | from: ../
2022-05-26 18:01:47,074 - DataLoaderLogger - INFO - DVC: CSV file read with path: data/merged/train.csv | version: merged_v1 | from: ../
2022-05-26 18:01:47,915 - DataLoaderLogger - INFO - DVC: CSV file read with path: data/merged/test.csv | version: merged_v1 | from: ../
2022-05-26 18:06:17,989 - DataLoaderLogger - INFO - DVC: CSV file read with path: data/cleaned/store.csv | version: stores_missing_filled | from: ../
2022-05-26 18:06:23,055 - DataLoaderLogger - INFO - DVC: CSV file read with path: data/raw/train.csv | version: raw_data | from: ../
2022-05-26 18:06:23,163 - DataLoaderLogger - INFO - DVC: CSV file read with path: data/raw/test.csv | version: raw_data | from: ../
2022-05-26 18:06:45,584 - DataLoaderLogger - INFO - DVC: CSV file read with path: data/cleaned/store.csv | version: stores_missing_filled_v2 | from: ../
2022-05-26 18:06:49,404 - DataLoaderLogger - INFO - DVC: CSV file read with path: data/raw/train.csv | version: raw_data | from: ../
2022-05-26 18:06:49,640 - DataLoaderLogger - INFO - DVC: CSV file read with path: data/raw/test.csv | version: raw_data | from: ../
2022-05-26 18:15:41,765 - DataLoaderLogger - INFO - DVC: CSV file read with path: data/merged/train.csv | version: merged_v2 | from: ../
2022-05-26 18:15:42,945 - DataLoaderLogger - INFO - DVC: CSV file read with path: data/merged/test.csv | version: merged_v2 | from: ../
2022-05-26 18:21:48,959 - DataLoaderLogger - INFO - DVC: CSV file read with path: data/merged/train.csv | version: merged_v3 | from: ../
2022-05-26 18:21:50,351 - DataLoaderLogger - INFO - DVC: CSV file read with path: data/merged/test.csv | version: merged_v3 | from: ../
2022-05-26 18:24:47,310 - DataLoaderLogger - INFO - DVC: CSV file read with path: data/merged/train.csv | version: merged_v3 | from: ../
2022-05-26 18:24:48,148 - DataLoaderLogger - INFO - DVC: CSV file read with path: data/merged/test.csv | version: merged_v3 | from: ../
2022-05-26 19:51:46,056 - DataLoaderLogger - INFO - DVC: CSV file read with path: data/merged/train.csv | version: merged_v3 | from: ../
2022-05-26 19:51:47,786 - DataLoaderLogger - INFO - DVC: CSV file read with path: data/merged/test.csv | version: merged_v3 | from: ../
2022-05-26 20:30:46,623 - DataLoaderLogger - INFO - DVC: CSV file read with path: data/merged/train.csv | version: merged_v3 | from: ../
2022-05-26 20:30:47,300 - DataLoaderLogger - INFO - DVC: CSV file read with path: data/merged/test.csv | version: merged_v3 | from: ../
2022-05-26 20:31:29,357 - DataLoaderLogger - INFO - DVC: CSV file read with path: data/merged/train.csv | version: merged_v3 | from: ../
2022-05-26 20:31:30,163 - DataLoaderLogger - INFO - DVC: CSV file read with path: data/merged/test.csv | version: merged_v3 | from: ../
2022-05-26 20:33:31,156 - DataLoaderLogger - INFO - DVC: CSV file read with path: data/merged/train.csv | version: merged_v3 | from: ../
2022-05-26 20:33:31,734 - DataLoaderLogger - INFO - DVC: CSV file read with path: data/merged/test.csv | version: merged_v3 | from: ../
2022-05-26 21:19:42,070 - DataLoaderLogger - INFO - DVC: CSV file read with path: data/merged/train.csv | version: merged_v3 | from: ../
2022-05-26 21:19:42,788 - DataLoaderLogger - INFO - DVC: CSV file read with path: data/merged/test.csv | version: merged_v3 | from: ../
2022-05-26 21:35:18,293 - DataLoaderLogger - INFO - DVC: CSV file read with path: data/merged/train.csv | version: merged_v3 | from: ../
2022-05-26 21:35:19,019 - DataLoaderLogger - INFO - DVC: CSV file read with path: data/merged/test.csv | version: merged_v3 | from: ../
2022-05-26 22:12:45,683 - DataLoaderLogger - INFO - DVC: CSV file read with path: data/merged/train.csv | version: merged_v3 | from: ../
2022-05-26 22:12:46,318 - DataLoaderLogger - INFO - DVC: CSV file read with path: data/merged/test.csv | version: merged_v3 | from: ../
2022-05-26 22:38:16,871 - DataLoaderLogger - INFO - DVC: CSV file read with path: data/merged/train.csv | version: merged_v3 | from: ../
2022-05-26 22:38:18,182 - DataLoaderLogger - INFO - DVC: CSV file read with path: data/merged/test.csv | version: merged_v3 | from: ../
2022-05-26 22:53:01,141 - DataLoaderLogger - INFO - DVC: CSV file read with path: data/merged/train.csv | version: merged_v3 | from: ../
2022-05-26 22:53:01,884 - DataLoaderLogger - INFO - DVC: CSV file read with path: data/merged/test.csv | version: merged_v3 | from: ../
2022-05-26 23:04:44,831 - DataLoaderLogger - INFO - DVC: CSV file read with path: data/merged/train.csv | version: merged_v3 | from: ../
2022-05-26 23:04:45,391 - DataLoaderLogger - INFO - DVC: CSV file read with path: data/merged/test.csv | version: merged_v3 | from: ../
2022-05-26 23:05:29,931 - DataLoaderLogger - INFO - DVC: CSV file read with path: data/merged/train.csv | version: merged_v3 | from: ../
2022-05-26 23:05:30,517 - DataLoaderLogger - INFO - DVC: CSV file read with path: data/merged/test.csv | version: merged_v3 | from: ../
2022-05-26 23:11:37,073 - DataLoaderLogger - INFO - DVC: CSV file read with path: data/merged/train.csv | version: merged_v3 | from: ../
2022-05-26 23:11:37,893 - DataLoaderLogger - INFO - DVC: CSV file read with path: data/merged/test.csv | version: merged_v3 | from: ../
2022-05-26 23:20:16,399 - DataLoaderLogger - INFO - DVC: CSV file read with path: data/merged/train.csv | version: merged_v3 | from: ../
2022-05-26 23:20:17,165 - DataLoaderLogger - INFO - DVC: CSV file read with path: data/merged/test.csv | version: merged_v3 | from: ../
2022-05-26 23:25:56,785 - DataLoaderLogger - INFO - DVC: CSV file read with path: data/merged/train.csv | version: merged_v3 | from: ../
2022-05-26 23:25:57,557 - DataLoaderLogger - INFO - DVC: CSV file read with path: data/merged/test.csv | version: merged_v3 | from: ../
2022-05-26 23:38:43,474 - DataLoaderLogger - INFO - DVC: CSV file read with path: data/merged/train.csv | version: merged_v3 | from: ../
2022-05-26 23:38:44,190 - DataLoaderLogger - INFO - DVC: CSV file read with path: data/merged/test.csv | version: merged_v3 | from: ../
2022-05-26 23:46:28,383 - DataLoaderLogger - INFO - DVC: CSV file read with path: data/merged/train.csv | version: merged_v3 | from: ../
2022-05-26 23:46:29,234 - DataLoaderLogger - INFO - DVC: CSV file read with path: data/merged/test.csv | version: merged_v3 | from: ../
2022-05-26 23:51:31,373 - DataLoaderLogger - INFO - DVC: CSV file read with path: data/merged/train.csv | version: merged_v3 | from: ../
2022-05-26 23:51:32,136 - DataLoaderLogger - INFO - DVC: CSV file read with path: data/merged/test.csv | version: merged_v3 | from: ../
2022-05-26 23:59:53,102 - DataLoaderLogger - INFO - DVC: CSV file read with path: data/merged/train.csv | version: merged_v3 | from: ../
2022-05-27 00:12:42,744 - DataLoaderLogger - INFO - DVC: CSV file read with path: data/merged/train.csv | version: merged_v3 | from: ../
2022-05-27 01:54:47,279 - DataLoaderLogger - INFO - DVC: CSV file read with path: data/merged/train.csv | version: merged_v3 | from: ../
2022-05-27 02:09:42,157 - DataLoaderLogger - INFO - DVC: CSV file read with path: data/merged/train.csv | version: merged_v3 | from: ../
2022-05-27 02:10:55,854 - DataLoaderLogger - INFO - DVC: CSV file read with path: data/merged/train.csv | version: merged_v3 | from: ../
2022-05-27 02:26:37,584 - DataLoaderLogger - INFO - DVC: CSV file read with path: data/merged/train.csv | version: merged_v3 | from: ../
2022-05-27 02:29:20,652 - DataLoaderLogger - INFO - DVC: CSV file read with path: data/merged/train.csv | version: merged_v3 | from: ../
2022-05-27 02:36:00,522 - DataLoaderLogger - INFO - DVC: CSV file read with path: data/merged/train.csv | version: merged_v3 | from: ../
2022-05-27 02:41:47,248 - DataLoaderLogger - INFO - DVC: CSV file read with path: data/merged/train.csv | version: merged_v3 | from: ../
2022-05-27 02:43:47,063 - DataLoaderLogger - INFO - DVC: CSV file read with path: data/merged/train.csv | version: merged_v3 | from: ../
2022-05-27 02:46:59,933 - DataLoaderLogger - INFO - DVC: CSV file read with path: data/merged/train.csv | version: merged_v3 | from: ../
2022-05-27 09:15:01,583 - DataLoaderLogger - INFO - DVC: CSV file read with path: data/merged/train.csv | version: merged_v3 | from: ../
2022-05-27 09:39:46,125 - DataLoaderLogger - INFO - DVC: CSV file read with path: data/merged/train.csv | version: merged_v3 | from: ../
2022-05-27 10:42:06,810 - DataLoaderLogger - INFO - DVC: CSV file read with path: data/merged/train.csv | version: merged_v3 | from: ../
2022-05-27 10:46:11,543 - DataLoaderLogger - INFO - DVC: CSV file read with path: data/merged/train.csv | version: merged_v3 | from: ../
2022-05-27 10:49:38,908 - DataLoaderLogger - INFO - DVC: CSV file read with path: data/merged/train.csv | version: merged_v3 | from: ../
2022-05-27 10:51:46,467 - DataLoaderLogger - INFO - DVC: CSV file read with path: data/merged/train.csv | version: merged_v3 | from: ../
2022-05-28 00:17:20,870 - DataLoaderLogger - ERROR - DVC data getter raised an exception
Traceback (most recent call last):
  File "/home/hat/dev-env/10Acadamy/week_3/Rossmann-Pharmaceuticals-Sales-Forcast/venv/lib/python3.10/site-packages/dvc/fs/dvc.py", line 68, in _get_fs_path
    remote_odb = self.repo.cloud.get_remote_odb(remote)
  File "/home/hat/dev-env/10Acadamy/week_3/Rossmann-Pharmaceuticals-Sales-Forcast/venv/lib/python3.10/site-packages/dvc/data_cloud.py", line 55, in get_remote_odb
    raise NoRemoteError(error_msg)
dvc.config.NoRemoteError: config file error: no remote specified. Create a default remote with
    dvc remote add -d <remote name> <remote url>

The above exception was the direct cause of the following exception:

Traceback (most recent call last):
  File "/home/hat/dev-env/10Acadamy/week_3/Rossmann-Pharmaceuticals-Sales-Forcast/venv/lib/python3.10/site-packages/dvc/repo/__init__.py", line 498, in open_by_relpath
    with fs.open(
  File "/home/hat/dev-env/10Acadamy/week_3/Rossmann-Pharmaceuticals-Sales-Forcast/venv/lib/python3.10/site-packages/dvc/fs/base.py", line 186, in open
    return self.fs.open(path, mode=mode, encoding=encoding, **kwargs)
  File "/home/hat/dev-env/10Acadamy/week_3/Rossmann-Pharmaceuticals-Sales-Forcast/venv/lib/python3.10/site-packages/dvc/fs/repo.py", line 309, in open
    return dvc_fs.open(dvc_path, mode=mode, encoding=encoding, **kwargs)
  File "/home/hat/dev-env/10Acadamy/week_3/Rossmann-Pharmaceuticals-Sales-Forcast/venv/lib/python3.10/site-packages/dvc/fs/base.py", line 186, in open
    return self.fs.open(path, mode=mode, encoding=encoding, **kwargs)
  File "/home/hat/dev-env/10Acadamy/week_3/Rossmann-Pharmaceuticals-Sales-Forcast/venv/lib/python3.10/site-packages/dvc/fs/dvc.py", line 77, in open
    fs, fspath = self._get_fs_path(path, **kwargs)
  File "/home/hat/dev-env/10Acadamy/week_3/Rossmann-Pharmaceuticals-Sales-Forcast/venv/lib/python3.10/site-packages/dvc/fs/dvc.py", line 70, in _get_fs_path
    raise FileNotFoundError from exc
FileNotFoundError

The above exception was the direct cause of the following exception:

Traceback (most recent call last):
  File "/home/hat/dev-env/10Acadamy/week_3/Rossmann-Pharmaceuticals-Sales-Forcast/notebooks/../src/fetch_data.py", line 25, in dvc_get_data
    content = dvc.api.read(path=path,
  File "/home/hat/dev-env/10Acadamy/week_3/Rossmann-Pharmaceuticals-Sales-Forcast/venv/lib/python3.10/site-packages/dvc/api.py", line 88, in read
    with open(
  File "/usr/lib/python3.10/contextlib.py", line 135, in __enter__
    return next(self.gen)
  File "/home/hat/dev-env/10Acadamy/week_3/Rossmann-Pharmaceuticals-Sales-Forcast/venv/lib/python3.10/site-packages/dvc/api.py", line 76, in _open
    with _repo.open_by_relpath(
  File "/usr/lib/python3.10/contextlib.py", line 135, in __enter__
    return next(self.gen)
  File "/home/hat/dev-env/10Acadamy/week_3/Rossmann-Pharmaceuticals-Sales-Forcast/venv/lib/python3.10/site-packages/dvc/repo/__init__.py", line 503, in open_by_relpath
    raise FileMissingError(path) from exc
dvc.exceptions.FileMissingError: Can't find 'data/raw/store.csv' neither locally nor on remote
2022-05-28 04:59:17,626 - DataLoaderLogger - ERROR - DVC data getter raised an exception
Traceback (most recent call last):
  File "/home/hat/dev-env/10Acadamy/week_3/Rossmann-Pharmaceuticals-Sales-Forcast/venv/lib/python3.10/site-packages/dvc/fs/dvc.py", line 68, in _get_fs_path
    remote_odb = self.repo.cloud.get_remote_odb(remote)
  File "/home/hat/dev-env/10Acadamy/week_3/Rossmann-Pharmaceuticals-Sales-Forcast/venv/lib/python3.10/site-packages/dvc/data_cloud.py", line 55, in get_remote_odb
    raise NoRemoteError(error_msg)
dvc.config.NoRemoteError: config file error: no remote specified. Create a default remote with
    dvc remote add -d <remote name> <remote url>

The above exception was the direct cause of the following exception:

Traceback (most recent call last):
  File "/home/hat/dev-env/10Acadamy/week_3/Rossmann-Pharmaceuticals-Sales-Forcast/venv/lib/python3.10/site-packages/dvc/repo/__init__.py", line 498, in open_by_relpath
    with fs.open(
  File "/home/hat/dev-env/10Acadamy/week_3/Rossmann-Pharmaceuticals-Sales-Forcast/venv/lib/python3.10/site-packages/dvc/fs/base.py", line 186, in open
    return self.fs.open(path, mode=mode, encoding=encoding, **kwargs)
  File "/home/hat/dev-env/10Acadamy/week_3/Rossmann-Pharmaceuticals-Sales-Forcast/venv/lib/python3.10/site-packages/dvc/fs/repo.py", line 309, in open
    return dvc_fs.open(dvc_path, mode=mode, encoding=encoding, **kwargs)
  File "/home/hat/dev-env/10Acadamy/week_3/Rossmann-Pharmaceuticals-Sales-Forcast/venv/lib/python3.10/site-packages/dvc/fs/base.py", line 186, in open
    return self.fs.open(path, mode=mode, encoding=encoding, **kwargs)
  File "/home/hat/dev-env/10Acadamy/week_3/Rossmann-Pharmaceuticals-Sales-Forcast/venv/lib/python3.10/site-packages/dvc/fs/dvc.py", line 77, in open
    fs, fspath = self._get_fs_path(path, **kwargs)
  File "/home/hat/dev-env/10Acadamy/week_3/Rossmann-Pharmaceuticals-Sales-Forcast/venv/lib/python3.10/site-packages/dvc/fs/dvc.py", line 70, in _get_fs_path
    raise FileNotFoundError from exc
FileNotFoundError

The above exception was the direct cause of the following exception:

Traceback (most recent call last):
  File "/home/hat/dev-env/10Acadamy/week_3/Rossmann-Pharmaceuticals-Sales-Forcast/notebooks/../src/fetch_data.py", line 25, in dvc_get_data
    content = dvc.api.read(path=path,
  File "/home/hat/dev-env/10Acadamy/week_3/Rossmann-Pharmaceuticals-Sales-Forcast/venv/lib/python3.10/site-packages/dvc/api.py", line 88, in read
    with open(
  File "/usr/lib/python3.10/contextlib.py", line 135, in __enter__
    return next(self.gen)
  File "/home/hat/dev-env/10Acadamy/week_3/Rossmann-Pharmaceuticals-Sales-Forcast/venv/lib/python3.10/site-packages/dvc/api.py", line 76, in _open
    with _repo.open_by_relpath(
  File "/usr/lib/python3.10/contextlib.py", line 135, in __enter__
    return next(self.gen)
  File "/home/hat/dev-env/10Acadamy/week_3/Rossmann-Pharmaceuticals-Sales-Forcast/venv/lib/python3.10/site-packages/dvc/repo/__init__.py", line 503, in open_by_relpath
    raise FileMissingError(path) from exc
dvc.exceptions.FileMissingError: Can't find 'data/raw/store.csv' neither locally nor on remote
2022-05-28 05:01:04,059 - DataLoaderLogger - INFO - DVC: CSV file read with path: data/raw/store.csv | version: raw_data | from: ../
2022-05-28 05:01:39,795 - DataLoaderLogger - INFO - DVC: CSV file read with path: data/raw/store.csv | version: raw_data | from: ../
2022-05-28 06:33:52,016 - DataLoaderLogger - INFO - DVC: CSV file read with path: data/merged/train.csv | version: merged_v3 | from: ../
2022-05-28 09:03:40,981 - DataLoaderLogger - INFO - DVC: CSV file read with path: data/merged/train.csv | version: merged_v3 | from: ../
2022-05-28 09:11:25,681 - DataLoaderLogger - INFO - DVC: CSV file read with path: data/merged/train.csv | version: merged_v3 | from: ../
2022-05-28 09:30:25,157 - DataLoaderLogger - INFO - DVC: CSV file read with path: data/merged/train.csv | version: merged_v3 | from: ../
2022-05-28 09:32:45,280 - DataLoaderLogger - INFO - DVC: CSV file read with path: data/merged/train.csv | version: merged_v3 | from: ../
2022-05-28 09:37:54,727 - DataLoaderLogger - INFO - DVC: CSV file read with path: data/merged/train.csv | version: merged_v3 | from: ../
2022-05-28 09:51:41,175 - DataLoaderLogger - INFO - DVC: CSV file read with path: data/merged/train.csv | version: merged_v3 | from: ../
2022-05-28 09:56:11,042 - DataLoaderLogger - INFO - DVC: CSV file read with path: data/merged/train.csv | version: merged_v3 | from: ../
2022-05-28 10:01:18,146 - DataLoaderLogger - INFO - DVC: CSV file read with path: data/merged/train.csv | version: merged_v3 | from: ../
2022-05-28 10:13:00,810 - DataLoaderLogger - INFO - DVC: CSV file read with path: data/merged/train.csv | version: merged_v3 | from: ../
2022-05-28 10:24:10,263 - DataLoaderLogger - INFO - DVC: CSV file read with path: data/merged/train.csv | version: merged_v3 | from: ../
2022-05-28 10:26:19,607 - DataLoaderLogger - INFO - DVC: CSV file read with path: data/merged/train.csv | version: merged_v3 | from: ../
2022-05-28 10:37:14,520 - DataLoaderLogger - INFO - DVC: CSV file read with path: data/merged/train.csv | version: merged_v3 | from: ../
